2025-03-11 16:49:45,671 INFO    Thread-13 :35436 [wandb_setup.py:_flush():67] Current SDK version is 0.19.8
2025-03-11 16:49:45,671 INFO    Thread-13 :35436 [wandb_setup.py:_flush():67] Configure stats pid to 35436
2025-03-11 16:49:45,671 INFO    Thread-13 :35436 [wandb_setup.py:_flush():67] Loading settings from /home/mezallamosas.j/.config/wandb/settings
2025-03-11 16:49:45,671 INFO    Thread-13 :35436 [wandb_setup.py:_flush():67] Loading settings from /home/mezallamosas.j/nlp2025/wandb/settings
2025-03-11 16:49:45,671 INFO    Thread-13 :35436 [wandb_setup.py:_flush():67] Loading settings from environment variables
2025-03-11 16:49:45,672 INFO    Thread-13 :35436 [wandb_init.py:setup_run_log_directory():647] Logging user logs to /home/mezallamosas.j/nlp2025/wandb/run-20250311_164945-epwtlmdu/logs/debug.log
2025-03-11 16:49:45,672 INFO    Thread-13 :35436 [wandb_init.py:setup_run_log_directory():648] Logging internal logs to /home/mezallamosas.j/nlp2025/wandb/run-20250311_164945-epwtlmdu/logs/debug-internal.log
2025-03-11 16:49:45,672 INFO    Thread-13 :35436 [wandb_init.py:monkeypatch_ipython():599] configuring jupyter hooks <wandb.sdk.wandb_init._WandbInit object at 0x2b328d918670>
2025-03-11 16:49:45,672 INFO    Thread-13 :35436 [wandb_init.py:init():761] calling init triggers
2025-03-11 16:49:45,672 INFO    Thread-13 :35436 [wandb_init.py:init():766] wandb.init called with sweep_config: {'batch_size': 16, 'embeddings_size': 50, 'epochs': 5, 'hidden_units': 64, 'lr': 0.001, 'ngram': 4, 'test_pct': 0.1, 'text_type': ['word']}
config: {'_wandb': {}}
2025-03-11 16:49:45,672 INFO    Thread-13 :35436 [wandb_init.py:init():784] starting backend
2025-03-11 16:49:45,672 INFO    Thread-13 :35436 [wandb_init.py:init():788] sending inform_init request
2025-03-11 16:49:45,675 INFO    Thread-13 :35436 [backend.py:_multiprocessing_setup():101] multiprocessing start_methods=fork,spawn,forkserver, using: spawn
2025-03-11 16:49:45,675 INFO    Thread-13 :35436 [wandb_init.py:init():798] backend started and connected
2025-03-11 16:49:45,695 INFO    Thread-13 :35436 [wandb_run.py:_config_callback():1261] config_cb None None {'batch_size': 16, 'embeddings_size': 50, 'epochs': 5, 'hidden_units': 64, 'lr': 0.001, 'ngram': 4, 'test_pct': 0.1, 'text_type': ['word']}
2025-03-11 16:49:45,700 INFO    Thread-13 :35436 [wandb_run.py:_label_probe_notebook():1204] probe notebook
2025-03-11 16:49:45,700 INFO    Thread-13 :35436 [wandb_run.py:_label_probe_notebook():1214] Unable to probe notebook: 'NoneType' object has no attribute 'get'
2025-03-11 16:49:45,700 INFO    Thread-13 :35436 [wandb_init.py:init():891] updated telemetry
2025-03-11 16:49:45,761 INFO    Thread-13 :35436 [wandb_init.py:init():915] communicating run to backend with 90.0 second timeout
2025-03-11 16:49:48,898 INFO    Thread-13 :35436 [wandb_init.py:init():990] starting run threads in backend
2025-03-11 16:49:48,966 ERROR   Thread-13 :35436 [wandb_init.py:init():1478] error in wandb.init()
Traceback (most recent call last):
  File "/home/mezallamosas.j/.conda/envs/nlp/lib/python3.9/site-packages/wandb/sdk/wandb_init.py", line 1468, in init
    return wi.init(run_settings, run_config)
  File "/home/mezallamosas.j/.conda/envs/nlp/lib/python3.9/site-packages/wandb/sdk/wandb_init.py", line 1031, in init
    run._on_start()
  File "/home/mezallamosas.j/.conda/envs/nlp/lib/python3.9/site-packages/wandb/sdk/wandb_run.py", line 2398, in _on_start
    self._header(settings=self._settings, printer=self._printer)
  File "/home/mezallamosas.j/.conda/envs/nlp/lib/python3.9/site-packages/wandb/sdk/wandb_run.py", line 3744, in _header
    Run._header_wandb_version_info(settings=settings, printer=printer)
  File "/home/mezallamosas.j/.conda/envs/nlp/lib/python3.9/site-packages/wandb/sdk/wandb_run.py", line 3758, in _header_wandb_version_info
    printer.display(f"Tracking run with wandb version {wandb.__version__}")
  File "/home/mezallamosas.j/.conda/envs/nlp/lib/python3.9/site-packages/wandb/sdk/lib/printer.py", line 460, in display
    self._ipython_display.display(self._ipython_display.HTML(text))
  File "/home/mezallamosas.j/.conda/envs/nlp/lib/python3.9/site-packages/IPython/core/display_functions.py", line 305, in display
    publish_display_data(data=format_dict, metadata=md_dict, **kwargs)
  File "/home/mezallamosas.j/.conda/envs/nlp/lib/python3.9/site-packages/IPython/core/display_functions.py", line 93, in publish_display_data
    display_pub.publish(
  File "/home/mezallamosas.j/.conda/envs/nlp/lib/python3.9/site-packages/wandb/sdk/wandb_init.py", line 610, in publish
    ipython.display_pub._orig_publish(data, metadata=metadata, **kwargs)
  File "/home/mezallamosas.j/.conda/envs/nlp/lib/python3.9/site-packages/ipykernel/zmqshell.py", line 103, in publish
    self._flush_streams()
  File "/home/mezallamosas.j/.conda/envs/nlp/lib/python3.9/site-packages/ipykernel/zmqshell.py", line 66, in _flush_streams
    sys.stdout.flush()
  File "/home/mezallamosas.j/.conda/envs/nlp/lib/python3.9/site-packages/ipykernel/iostream.py", line 604, in flush
    self.pub_thread.schedule(self._flush)
  File "/home/mezallamosas.j/.conda/envs/nlp/lib/python3.9/site-packages/ipykernel/iostream.py", line 267, in schedule
    self._event_pipe.send(b"")
  File "/home/mezallamosas.j/.conda/envs/nlp/lib/python3.9/site-packages/zmq/sugar/socket.py", line 707, in send
    return super().send(data, flags=flags, copy=copy, track=track)
  File "_zmq.py", line 1092, in zmq.backend.cython._zmq.Socket.send
  File "_zmq.py", line 1134, in zmq.backend.cython._zmq.Socket.send
  File "_zmq.py", line 1209, in zmq.backend.cython._zmq._check_closed
zmq.error.ZMQError: Socket operation on non-socket
2025-03-11 16:49:49,032 INFO    MainThread:35436 [wandb_init.py:_resume_backend():569] resuming backend
2025-03-11 16:49:49,126 INFO    Thread-13 :35436 [wandb_run.py:_finish():2112] finishing run biofx/neural-language-model/epwtlmdu
2025-03-11 16:49:49,126 INFO    Thread-13 :35436 [jupyter.py:save_history():458] not saving jupyter history
2025-03-11 16:49:49,127 INFO    Thread-13 :35436 [jupyter.py:save_ipynb():386] not saving jupyter notebook
2025-03-11 16:49:49,128 INFO    Thread-13 :35436 [wandb_init.py:_jupyter_teardown():581] cleaning up jupyter logic
2025-03-11 16:49:49,128 INFO    Thread-13 :35436 [wandb_run.py:_atexit_cleanup():2340] got exitcode: 1
2025-03-11 16:49:49,128 INFO    Thread-13 :35436 [wandb_run.py:_restore():2322] restore
2025-03-11 16:49:49,128 INFO    Thread-13 :35436 [wandb_run.py:_restore():2328] restore done
2025-03-11 16:49:49,140 INFO    Thread-13 :35436 [wandb_run.py:_restore():2322] restore
2025-03-11 16:49:49,143 INFO    Thread-13 :35436 [wandb_run.py:_restore():2328] restore done
2025-03-11 16:49:49,143 ERROR   Thread-13 :35436 [wandb_run.py:_atexit_cleanup():2361] Problem finishing run
Traceback (most recent call last):
  File "/home/mezallamosas.j/.conda/envs/nlp/lib/python3.9/site-packages/wandb/agents/pyagent.py", line 306, in _run_job
    self._function()
  File "/tmp/ipykernel_35436/499683083.py", line 3, in main
    wandb.init(
  File "/home/mezallamosas.j/.conda/envs/nlp/lib/python3.9/site-packages/wandb/sdk/wandb_init.py", line 1482, in init
    wandb._sentry.reraise(e)
  File "/home/mezallamosas.j/.conda/envs/nlp/lib/python3.9/site-packages/wandb/analytics/sentry.py", line 156, in reraise
    raise exc.with_traceback(sys.exc_info()[2])
  File "/home/mezallamosas.j/.conda/envs/nlp/lib/python3.9/site-packages/wandb/sdk/wandb_init.py", line 1468, in init
    return wi.init(run_settings, run_config)
  File "/home/mezallamosas.j/.conda/envs/nlp/lib/python3.9/site-packages/wandb/sdk/wandb_init.py", line 1031, in init
    run._on_start()
  File "/home/mezallamosas.j/.conda/envs/nlp/lib/python3.9/site-packages/wandb/sdk/wandb_run.py", line 2398, in _on_start
    self._header(settings=self._settings, printer=self._printer)
  File "/home/mezallamosas.j/.conda/envs/nlp/lib/python3.9/site-packages/wandb/sdk/wandb_run.py", line 3744, in _header
    Run._header_wandb_version_info(settings=settings, printer=printer)
  File "/home/mezallamosas.j/.conda/envs/nlp/lib/python3.9/site-packages/wandb/sdk/wandb_run.py", line 3758, in _header_wandb_version_info
    printer.display(f"Tracking run with wandb version {wandb.__version__}")
  File "/home/mezallamosas.j/.conda/envs/nlp/lib/python3.9/site-packages/wandb/sdk/lib/printer.py", line 460, in display
    self._ipython_display.display(self._ipython_display.HTML(text))
  File "/home/mezallamosas.j/.conda/envs/nlp/lib/python3.9/site-packages/IPython/core/display_functions.py", line 305, in display
    publish_display_data(data=format_dict, metadata=md_dict, **kwargs)
  File "/home/mezallamosas.j/.conda/envs/nlp/lib/python3.9/site-packages/IPython/core/display_functions.py", line 93, in publish_display_data
    display_pub.publish(
  File "/home/mezallamosas.j/.conda/envs/nlp/lib/python3.9/site-packages/wandb/sdk/wandb_init.py", line 610, in publish
    ipython.display_pub._orig_publish(data, metadata=metadata, **kwargs)
  File "/home/mezallamosas.j/.conda/envs/nlp/lib/python3.9/site-packages/ipykernel/zmqshell.py", line 103, in publish
    self._flush_streams()
  File "/home/mezallamosas.j/.conda/envs/nlp/lib/python3.9/site-packages/ipykernel/zmqshell.py", line 66, in _flush_streams
    sys.stdout.flush()
  File "/home/mezallamosas.j/.conda/envs/nlp/lib/python3.9/site-packages/ipykernel/iostream.py", line 604, in flush
    self.pub_thread.schedule(self._flush)
  File "/home/mezallamosas.j/.conda/envs/nlp/lib/python3.9/site-packages/ipykernel/iostream.py", line 267, in schedule
    self._event_pipe.send(b"")
  File "/home/mezallamosas.j/.conda/envs/nlp/lib/python3.9/site-packages/zmq/sugar/socket.py", line 707, in send
    return super().send(data, flags=flags, copy=copy, track=track)
  File "_zmq.py", line 1092, in zmq.backend.cython._zmq.Socket.send
  File "_zmq.py", line 1134, in zmq.backend.cython._zmq.Socket.send
  File "_zmq.py", line 1209, in zmq.backend.cython._zmq._check_closed
zmq.error.ZMQError: Socket operation on non-socket

During handling of the above exception, another exception occurred:

Traceback (most recent call last):
  File "/home/mezallamosas.j/.conda/envs/nlp/lib/python3.9/site-packages/wandb/sdk/wandb_run.py", line 2352, in _atexit_cleanup
    self._on_finish()
  File "/home/mezallamosas.j/.conda/envs/nlp/lib/python3.9/site-packages/wandb/sdk/wandb_run.py", line 2604, in _on_finish
    with progress.progress_printer(
  File "/home/mezallamosas.j/.conda/envs/nlp/lib/python3.9/contextlib.py", line 119, in __enter__
    return next(self.gen)
  File "/home/mezallamosas.j/.conda/envs/nlp/lib/python3.9/site-packages/wandb/sdk/lib/progress.py", line 92, in progress_printer
    with printer.dynamic_text() as text_area:
  File "/home/mezallamosas.j/.conda/envs/nlp/lib/python3.9/contextlib.py", line 119, in __enter__
    return next(self.gen)
  File "/home/mezallamosas.j/.conda/envs/nlp/lib/python3.9/site-packages/wandb/sdk/lib/printer.py", line 436, in dynamic_text
    handle = self._ipython_display.display(
  File "/home/mezallamosas.j/.conda/envs/nlp/lib/python3.9/site-packages/IPython/core/display_functions.py", line 305, in display
    publish_display_data(data=format_dict, metadata=md_dict, **kwargs)
  File "/home/mezallamosas.j/.conda/envs/nlp/lib/python3.9/site-packages/IPython/core/display_functions.py", line 93, in publish_display_data
    display_pub.publish(
  File "/home/mezallamosas.j/.conda/envs/nlp/lib/python3.9/site-packages/ipykernel/zmqshell.py", line 103, in publish
    self._flush_streams()
  File "/home/mezallamosas.j/.conda/envs/nlp/lib/python3.9/site-packages/ipykernel/zmqshell.py", line 66, in _flush_streams
    sys.stdout.flush()
  File "/home/mezallamosas.j/.conda/envs/nlp/lib/python3.9/site-packages/ipykernel/iostream.py", line 604, in flush
    self.pub_thread.schedule(self._flush)
  File "/home/mezallamosas.j/.conda/envs/nlp/lib/python3.9/site-packages/ipykernel/iostream.py", line 267, in schedule
    self._event_pipe.send(b"")
  File "/home/mezallamosas.j/.conda/envs/nlp/lib/python3.9/site-packages/zmq/sugar/socket.py", line 707, in send
    return super().send(data, flags=flags, copy=copy, track=track)
  File "_zmq.py", line 1092, in zmq.backend.cython._zmq.Socket.send
  File "_zmq.py", line 1134, in zmq.backend.cython._zmq.Socket.send
  File "_zmq.py", line 1209, in zmq.backend.cython._zmq._check_closed
zmq.error.ZMQError: Socket operation on non-socket
